---
layout: post
title: Java中的异常
date: 2022-05-30 21:22:13 +0800
categories: [JavaSE]
tags: [开发语言,java]
image:
    path: https://img-blog.csdnimg.cn/b3097e573c674c35add84935c72c9811.png?x-oss-process=image/resize,m_fixed,h_150
    alt: Java中的异常
artid: 125040373
render_with_liquid: false
---
<div class="blog-content-box">
 <div class="article-header-box">
  <div class="article-header">
   <div class="article-title-box">
    <h1 class="title-article" id="articleContentId">
     Java中的异常
    </h1>
   </div>
  </div>
 </div>
 <article class="baidu_pl">
  <div class="article_content clearfix" id="article_content">
   <link href="../../assets/css/kdoc_html_views-1a98987dfd.css" rel="stylesheet"/>
   <link href="../../assets/css/ck_htmledit_views-704d5b9767.css" rel="stylesheet"/>
   <div class="htmledit_views" id="content_views">
    <p>
    </p>
    <p id="main-toc">
     <strong>
      目录
     </strong>
    </p>
    <p id="1.%20%E5%BC%82%E5%B8%B8%E4%BA%A7%E7%94%9F%E7%9A%84%E5%8E%9F%E5%9B%A0%E5%92%8C%E5%88%86%E7%B1%BB-toc" style="margin-left:0px;">
     <a href="#1.%20%E5%BC%82%E5%B8%B8%E4%BA%A7%E7%94%9F%E7%9A%84%E5%8E%9F%E5%9B%A0%E5%92%8C%E5%88%86%E7%B1%BB" rel="nofollow">
      1. 异常产生的原因和分类
     </a>
    </p>
    <p id="1.1%20%E5%BC%82%E5%B8%B8%E4%BA%A7%E7%94%9F%E7%9A%84%E5%8E%9F%E5%9B%A0-toc" style="margin-left:40px;">
     <a href="#1.1%20%E5%BC%82%E5%B8%B8%E4%BA%A7%E7%94%9F%E7%9A%84%E5%8E%9F%E5%9B%A0" rel="nofollow">
      1.1 异常产生的原因
     </a>
    </p>
    <p id="1.2%20%E5%BC%82%E5%B8%B8%E5%88%86%E7%B1%BB-toc" style="margin-left:40px;">
     <a href="#1.2%20%E5%BC%82%E5%B8%B8%E5%88%86%E7%B1%BB" rel="nofollow">
      1.2 异常分类
     </a>
    </p>
    <p id="2.%20%E5%BC%82%E5%B8%B8%E7%9A%84%E5%A4%84%E7%90%86-toc" style="margin-left:0px;">
     <a href="#2.%20%E5%BC%82%E5%B8%B8%E7%9A%84%E5%A4%84%E7%90%86" rel="nofollow">
      2. 异常的处理
     </a>
    </p>
    <p id="2.1%20%E9%98%B2%E5%BE%A1%E5%BC%8F%E7%BC%96%E7%A8%8B-toc" style="margin-left:40px;">
     <a href="#2.1%20%E9%98%B2%E5%BE%A1%E5%BC%8F%E7%BC%96%E7%A8%8B" rel="nofollow">
      2.1 防御式编程
     </a>
    </p>
    <p id="2.2%20%E5%BC%82%E5%B8%B8%E7%9A%84%E6%8A%9B%E5%87%BA%EF%BC%88throw%EF%BC%89-toc" style="margin-left:40px;">
     <a href="#2.2%20%E5%BC%82%E5%B8%B8%E7%9A%84%E6%8A%9B%E5%87%BA%EF%BC%88throw%EF%BC%89" rel="nofollow">
      2.2 异常的抛出（throw）
     </a>
    </p>
    <p id="2.3%20%E5%BC%82%E5%B8%B8%E7%9A%84%E6%8D%95%E8%8E%B7-toc" style="margin-left:40px;">
     <a href="#2.3%20%E5%BC%82%E5%B8%B8%E7%9A%84%E6%8D%95%E8%8E%B7" rel="nofollow">
      2.3 异常的捕获
     </a>
    </p>
    <p id="2.3.1%20throws%E5%BC%82%E5%B8%B8%E5%A3%B0%E6%98%8E-toc" style="margin-left:80px;">
     <a href="#2.3.1%20throws%E5%BC%82%E5%B8%B8%E5%A3%B0%E6%98%8E" rel="nofollow">
      2.3.1 throws异常声明
     </a>
    </p>
    <p id="2.3.2%20try-catch%E6%8D%95%E8%8E%B7%E5%BC%82%E5%B8%B8%E5%B9%B6%E5%A4%84%E7%90%86-toc" style="margin-left:80px;">
     <a href="#2.3.2%20try-catch%E6%8D%95%E8%8E%B7%E5%BC%82%E5%B8%B8%E5%B9%B6%E5%A4%84%E7%90%86" rel="nofollow">
      2.3.2 try-catch捕获异常并处理
     </a>
    </p>
    <p id="2.3.3%20finally-toc" style="margin-left:80px;">
     <a href="#2.3.3%20finally" rel="nofollow">
      2.3.3 finally
     </a>
    </p>
    <p id="3.%E8%87%AA%E5%AE%9A%E4%B9%89%E5%BC%82%E5%B8%B8%E7%B1%BB-toc" style="margin-left:0px;">
     <a href="#3.%E8%87%AA%E5%AE%9A%E4%B9%89%E5%BC%82%E5%B8%B8%E7%B1%BB" rel="nofollow">
      3.自定义异常类
     </a>
    </p>
    <hr id="hr-toc"/>
    <p>
    </p>
    <blockquote>
     <p>
      <strong>
       <span style="color:#fe2c24;">
        Java中的异常（Exception）又称为例外，是一个在程序执行期间发生的事件，它中断正在执行程序的正常指令流。为了能够及时有效地处理程序中的运行错误，必须使用异常类。
       </span>
      </strong>
     </p>
    </blockquote>
    <h2 id="1.%20%E5%BC%82%E5%B8%B8%E4%BA%A7%E7%94%9F%E7%9A%84%E5%8E%9F%E5%9B%A0%E5%92%8C%E5%88%86%E7%B1%BB">
     <span style="color:#956fe7;">
      1. 异常产生的原因和分类
     </span>
    </h2>
    <h3 id="1.1%20%E5%BC%82%E5%B8%B8%E4%BA%A7%E7%94%9F%E7%9A%84%E5%8E%9F%E5%9B%A0">
     <span style="color:#1c7331;">
      1.1 异常产生的原因
     </span>
    </h3>
    <p>
     <span style="color:#0d0016;">
      <strong>
       ⚜️ 在Java中异常产生，主要是有三种原因：
      </strong>
     </span>
    </p>
    <blockquote>
     <p>
      <span style="color:#956fe7;">
       <strong>
        （1）编写程序代码中的错误产生的异常，比如数组越界、空指针异常等，这种异常叫做未检查的异常，一般需要在类中处理这些异常
       </strong>
      </span>
     </p>
     <p>
     </p>
     <p>
      <span style="color:#4da8ee;">
       <strong>
        （2）Java内部错误发生的异常，Java虚拟机产生异常
       </strong>
      </span>
     </p>
     <p>
     </p>
     <p>
      <span style="color:#a2e043;">
       <strong>
        （3）通过throw（抛出异常）语句手动生成的异常，这种异常叫做检查的异常，一般是用来给方法调用者一些必要的信息
       </strong>
      </span>
     </p>
    </blockquote>
    <h3 id="1.2%20%E5%BC%82%E5%B8%B8%E5%88%86%E7%B1%BB">
     <span style="color:#ad720d;">
      1.2 异常分类
     </span>
    </h3>
    <p style="text-align:center;">
     <img alt="" height="552" src="https://i-blog.csdnimg.cn/blog_migrate/ccb2dacb2ca85d780448655e72ce44fc.png" width="800"/>
    </p>
    <p>
    </p>
    <blockquote>
     <p>
      <span style="color:#fe2c24;">
       <strong>
        （1）Throwable：是异常体系的顶层类，其派生出两个重要的子类, Error 和 Exception
       </strong>
      </span>
     </p>
     <p>
      <span style="color:#fe2c24;">
       <strong>
        而 Error 和 Exception 两子类分别表示错误和异常。
       </strong>
      </span>
     </p>
     <p>
      <strong>
       <span style="color:#956fe7;">
        区别就是不检查异常（Unchecked Exception）和检查异常（Checked Exception）
       </span>
       。
      </strong>
     </p>
     <p>
      <strong>
       <span style="color:#4da8ee;">
        （2）Exception 类用于用户程序可能出现的异常情况，它也是用来创建自定义异常类型类的类。
       </span>
      </strong>
     </p>
     <p>
      <span style="color:#ff9900;">
       <strong>
        （3）Error 定义了在通常环境下不希望被程序捕获的异常。Error 类型的异常用于 Java 运行时由系统显示与运行时系统本身有关的错误。堆栈溢出是这种错误的一例。
       </strong>
      </span>
     </p>
    </blockquote>
    <p>
     <span style="color:#0d0016;">
      <strong>
       ⚜️  异常可能在编译时发生，也有可能在程序运行时发生，根据发生时机不同，可以分为：
      </strong>
     </span>
    </p>
    <blockquote>
     <p>
      <span style="color:#fe2c24;">
       <strong>
        运行时异常都是 RuntimeException 类及其子类异常，如 NullPointerException、IndexOutOfBoundsException 等，这些异常是不检查异常，程序中可以选择捕获处理，也可以不处理。这些异常一般由程序逻辑错误引起，程序应该从逻辑角度尽可能避免这类异常的发生。
       </strong>
      </span>
     </p>
    </blockquote>
    <p>
     比如：
    </p>
    <p>
     <img alt="" height="280" src="https://i-blog.csdnimg.cn/blog_migrate/c38d0ebdcc2b19d81d2385fb7d9331aa.png" width="784"/>
    </p>
    <p>
    </p>
    <blockquote>
     <p>
      <span style="color:#ff9900;">
       <strong>
        编译时异常是指 RuntimeException 以外的异常，类型上都属于 Exception 类及其子类。从程序语法角度讲是必须进行处理的异常，如果不处理，程序就不能编译通过。如 IOException、ClassNotFoundException 等以及用户自定义的 Exception 异常，一般情况下不自定义检查异常。
       </strong>
      </span>
     </p>
    </blockquote>
    <p>
     比如
    </p>
    <pre><code class="language-java">class Person implements Cloneable{
    @Override
    protected Object clone() throws CloneNotSupportedException {
        return super.clone();
    }
}
public class Test01 {

    public static void main(String[] args) {
        Person person =new Person();
        Person person1 =(Person) person.clone();
    }
}
</code></pre>
    <p>
     <img alt="" height="106" src="https://i-blog.csdnimg.cn/blog_migrate/fda9aa3a5f5d8454c3530f069db6cf7e.png" width="999"/>
    </p>
    <hr/>
    <p>
    </p>
    <p>
    </p>
    <h2 id="2.%20%E5%BC%82%E5%B8%B8%E7%9A%84%E5%A4%84%E7%90%86">
     <span style="color:#be191c;">
      2. 异常的处理
     </span>
    </h2>
    <h3 id="2.1%20%E9%98%B2%E5%BE%A1%E5%BC%8F%E7%BC%96%E7%A8%8B">
     <span style="color:#ad720d;">
      2.1 防御式编程
     </span>
    </h3>
    <p>
     <span style="color:#333333;">
      错误在代码中是客观存在的
     </span>
     <span style="color:#333333;">
      . 所以
     </span>
     <span style="color:#333333;">
      要让程序出现问题的时候快速通知程序猿
     </span>
     <span style="color:#333333;">
      .
     </span>
    </p>
    <p>
     通知有两种方式：
    </p>
    <p>
     <span style="color:#fe2c24;">
      <strong>
       🤠（1）LBYL 在操作之前就做充分的检查
      </strong>
     </span>
    </p>
    <pre><code class="language-java">private static int divide() {
        int a = 0, b = 0;
        Scanner scanner = new Scanner(System.in);
        a = scanner.nextInt();
        b = scanner.nextInt();
        if (b == 0) {
            System.out.println("除数为0");
            return 0;
        } else {
            return a / b;
        }
    }
</code></pre>
    <p>
     <span style="color:#0d0016;">
      <strong>
       缺点：正常流程和错误处理流程代码混在一起, 代码整体条理不清晰。
      </strong>
     </span>
     <span style="color:#333333;">
     </span>
    </p>
    <p>
     <span style="color:#ff9900;">
      <strong>
       🤠 （2）EAFP 先操作遇到问题再处理
      </strong>
     </span>
    </p>
    <pre><code class="language-java">private static int divide() {
        int a = 0, b = 0;
        try (Scanner scanner = new Scanner(System.in)) {
            a = scanner.nextInt();
            b = scanner.nextInt();
            return a / b;
        } catch (ArithmeticException exception) {
            System.out.println("除数为0");
            return 0;
        } 
    }
</code></pre>
    <p>
     <span style="color:#0d0016;">
      <strong>
       优点：正常流程和错误流程是分离开的, 程序员更关注正常流程，代码更清晰，容易理解代码
      </strong>
     </span>
    </p>
    <blockquote>
     <p>
      <span style="color:#956fe7;">
       <strong>
        处理异常的核心思想就是EAFP
       </strong>
      </span>
     </p>
    </blockquote>
    <hr/>
    <p>
    </p>
    <h3 id="2.2%20%E5%BC%82%E5%B8%B8%E7%9A%84%E6%8A%9B%E5%87%BA%EF%BC%88throw%EF%BC%89">
     <span style="color:#1c7331;">
      2.2 异常的抛出（throw）
     </span>
    </h3>
    <blockquote>
     <div>
      <span style="color:#fe2c24;">
       <strong>
        在编写程序时，如果程序中出现错误，这就需要将错误的信息通知给调用者
       </strong>
      </span>
     </div>
     <div>
     </div>
     <div>
      <span style="color:#956fe7;">
       <strong>
        这里就可以借助关键字throw，抛出一个指定的异常对象，将错误信息告知给调用者。
       </strong>
      </span>
     </div>
     <div>
     </div>
    </blockquote>
    <div>
    </div>
    <p>
     <span style="color:#a2e043;">
      <strong>
       🤠 比如写一个运行时异常
      </strong>
     </span>
    </p>
    <pre><code class="language-java">    public static void func2(int a) {
        if(a == 0) {
           //抛出的是一个指定的异常，最多的使用方式是，抛出一个自定义的异常
            throw new RuntimeException("a==0");
        }
    }
    public static void main(String[] args) {
        func2(0);
    }</code></pre>
    <p>
     <img alt="" height="103" src="https://i-blog.csdnimg.cn/blog_migrate/501605bc958da93545f6c2e8dba0a460.png" width="903">
      注意：
     </img>
    </p>
    <blockquote>
     <p>
      <span style="color:#fe2c24;">
       <strong>
        （1）throw必须写在方法体内部
       </strong>
      </span>
     </p>
     <p>
     </p>
     <p>
      <span style="color:#956fe7;">
       <strong>
        （2）如果抛出的是编译时异常，用户就必须要处理，否则无法通过编译
       </strong>
      </span>
     </p>
     <p>
      <span style="color:#0d0016;">
       <img alt="" height="187" src="https://i-blog.csdnimg.cn/blog_migrate/141896181243488e7d3b0b8bd66828b7.png" width="992"/>
      </span>
     </p>
     <p>
      <span style="color:#4da8ee;">
       <strong>
        （3）如果抛出的运行时异常，则可以不用处理，直接交给JVM来处理
       </strong>
      </span>
     </p>
     <p>
     </p>
     <p>
      <span style="color:#ff9900;">
       <strong>
        （4）一旦出现异常，后面的代码就不会执行
       </strong>
      </span>
     </p>
     <p>
      <img alt="" height="216" src="https://i-blog.csdnimg.cn/blog_migrate/19e38437389fb6faa6abf057d671c93f.png" width="462"/>
     </p>
     <p>
     </p>
    </blockquote>
    <hr/>
    <p>
    </p>
    <h3 id="2.3%20%E5%BC%82%E5%B8%B8%E7%9A%84%E6%8D%95%E8%8E%B7">
     <span style="color:#956fe7;">
      2.3 异常的捕获
     </span>
    </h3>
    <h4 id="2.3.1%20throws%E5%BC%82%E5%B8%B8%E5%A3%B0%E6%98%8E">
     <span style="color:#ff9900;">
      2.3.1 throws异常声明
     </span>
    </h4>
    <p>
     <img alt="" height="238" src="https://i-blog.csdnimg.cn/blog_migrate/669a72b4eb4561d2816c8c14bf213310.png" width="966"/>
    </p>
    <blockquote>
     <div>
      <span style="color:#fe2c24;">
       <strong>
        🤠  throws处在方法声明时参数列表之后，当方法中抛出编译时异常，用户不想处理该异常，
       </strong>
      </span>
     </div>
     <div>
      <span style="color:#fe2c24;">
       <strong>
        此时就可以借助throws将异常抛 给方法的调用者来处理。
       </strong>
      </span>
     </div>
     <div>
     </div>
     <div>
      <div>
       <span style="color:#956fe7;">
        <strong>
         格式：
        </strong>
       </span>
      </div>
      <div>
       <span style="color:#956fe7;">
        <strong>
         修饰符 返回值类型 方法名(参数列表) throws 异常类型 {
        </strong>
       </span>
      </div>
      <div>
      </div>
      <div>
       <span style="color:#956fe7;">
        <strong>
         }
        </strong>
       </span>
      </div>
     </div>
    </blockquote>
    <div>
     <span style="color:#1c7331;">
      <strong>
       🤠 如果说方法内部抛出了多个异常，throws之后就必须跟多个异常类型，用逗号进行分隔
      </strong>
     </span>
    </div>
    <div>
    </div>
    <div>
     <pre><code class="language-java">    public static void func2(int a) throws CloneNotSupportedException, FileNotFoundException {
        if(a == 0) {
            throw new CloneNotSupportedException("a==0");
        }
        if(a == 1) {
            throw new FileNotFoundException();
        }
    }
</code></pre>
     <p>
      <span style="color:#1c7331;">
       <strong>
        🤠  如果抛出多个异常类型有父子关系，直接声明父类
       </strong>
      </span>
     </p>
     <pre><code class="language-java">    public static void func2(int a) throws Exception {
        if(a == 0) {
            throw new CloneNotSupportedException("a==0");
        }
        if(a == 1) {
            throw new FileNotFoundException();
        }
    }</code></pre>
     <div>
      <span style="color:#fe2c24;">
       <strong>
        🤠 调用声明抛出异常的方法时，调用者必须对该异常进行处理，或者继续使用throws抛出
       </strong>
      </span>
     </div>
    </div>
    <pre><code class="language-java">   public static void main(String[] args) throws FileNotFoundException, CloneNotSupportedException {
        func2(0);
    }</code></pre>
    <hr/>
    <p>
    </p>
    <h4 id="2.3.2%20try-catch%E6%8D%95%E8%8E%B7%E5%BC%82%E5%B8%B8%E5%B9%B6%E5%A4%84%E7%90%86">
     <span style="color:#4da8ee;">
      <strong>
       2.3.2 try-catch捕获异常并处理
      </strong>
     </span>
    </h4>
    <p>
     <span style="color:#0d0016;">
      <strong>
       当程序抛出异常的时候，程序员通过try-each处理了异常
      </strong>
     </span>
    </p>
    <pre><code class="language-java">    public static void main(String[] args) {
        try {
            int[] array = null;
            System.out.println(array.length);
        }catch (NullPointerException e) {
            System.out.println("捕获到了一个空指针异常！");
        }
        System.out.println("其他程序！");
    }</code></pre>
    <p>
     <strong>
      如果程序抛出异常，不处理异常，那就会交给JVM处理，JVM处理就会把程序立即终止
     </strong>
    </p>
    <p>
     <span style="color:#0d0016;">
      <strong>
       并且，即使用了try-each 也必须捕获一个对应的异常，如果不是对应异常，也会让JVM进行处理
      </strong>
     </span>
    </p>
    <p>
     <img alt="" height="489" src="https://i-blog.csdnimg.cn/blog_migrate/c6b227a61d1d09aedf9f5ea8937e5b49.png" width="1135"/>
    </p>
    <p>
     <span style="color:#fe2c24;">
      <strong>
       🤠  如果try抛出多个异常，就必须用多个catch进行捕获
      </strong>
     </span>
    </p>
    <p>
     <span style="color:#fe2c24;">
      <strong>
       这里注意，用多个catch
      </strong>
     </span>
     <span style="color:#fe2c24;">
      <strong>
       进行捕获，不是同时进行捕获的，因为不可能同时抛不同的异常
      </strong>
     </span>
    </p>
    <pre><code class="language-java">    public static void main(String[] args) {
        try {
            int[] array = null;
            System.out.println(array.length);
        }catch (NullPointerException e) {
            System.out.println("捕获到了一个空指针异常！");
        }catch (ArithmeticException e) {
            System.out.println("捕获到了一个算术异常！");
        }
        System.out.println("其它代码逻辑！");
    }</code></pre>
    <p>
     也可以简写一下
    </p>
    <pre><code class="language-java">    public static void main(String[] args) {
        try {
            int[] array = null;
            System.out.println(array.length);
        }catch (NullPointerException  | ArithmeticException e) {
            System.out.println("捕获到了一个空指针或算术异常！");
        }
        System.out.println("其它代码逻辑！");
    }</code></pre>
    <p>
     <span style="color:#fe2c24;">
      <strong>
       🤠 如果异常之间具有父子关系，那就必须子类异常在前，父类异常在后catch，不然会报错
      </strong>
     </span>
    </p>
    <pre><code class="language-java">    public static void main(String[] args) {
        try {
            int[] array = null;
            System.out.println(array.length);
        }catch (NullPointerException e) {
            System.out.println("捕获到了一个空指针异常！");
        }catch (Exception) {
            System.out.println("捕获到了一个算术异常！");
        }
        System.out.println("其它代码逻辑！");
    }</code></pre>
    <hr/>
    <h4 id="2.3.3%20finally">
     <span style="color:#956fe7;">
      2.3.3 finally
     </span>
    </h4>
    <blockquote>
     <p>
      <span style="color:#ff9900;">
       <strong>
        🤠 finally用来进行资源回收，不论程序正常运行还是退出，都需要回收资源
       </strong>
      </span>
     </p>
     <p>
     </p>
     <p>
      <span style="color:#ff9900;">
       <strong>
        并且异常会引发程序的跳转，可能会导致有些语句执行不到
       </strong>
      </span>
     </p>
    </blockquote>
    <pre><code class="language-java">    public static void main(String[] args) {
        Scanner scanner = new Scanner(System.in);
        try {
            int[] array = null;
            System.out.println(array.length);
        }catch (NullPointerException e) {
            System.out.println("捕获到了一个空指针异常！");
        }catch (ArithmeticException e) {
            System.out.println("捕获到了一个算术异常！");
        }finally {
            scanner.close();
            System.out.println("进行资源关闭！");
        }
        System.out.println("其它代码逻辑！");
    }</code></pre>
    <p>
     <img alt="" height="111" src="https://i-blog.csdnimg.cn/blog_migrate/0832081b983f85be08f288cff6e8e72f.png" width="282"/>
    </p>
    <p>
     <span style="color:#fe2c24;">
      <strong>
       如果不为空，那么finally还会被执行吗
      </strong>
     </span>
    </p>
    <pre><code class="language-java">    public static void main(String[] args) {
        Scanner scanner = new Scanner(System.in);
        try {
            int[] array = {1,2,3};
            System.out.println(array.length);
        }catch (NullPointerException e) {
            System.out.println("捕获到了一个空指针异常！");
        }catch (ArithmeticException e) {
            System.out.println("捕获到了一个算术异常！");
        }finally {
            scanner.close();
            System.out.println("进行资源关闭！");
        }
        System.out.println("其它代码逻辑！");
    }</code></pre>
    <p>
     <img alt="" height="117" src="https://i-blog.csdnimg.cn/blog_migrate/4d6083ae7359ef351e0206d33b4fdf87.png" width="229"/>
    </p>
    <p>
     <span style="color:#0d0016;">
      <strong>
       所以，不管程序会不会抛出异常，finally都会执行
      </strong>
     </span>
    </p>
    <p>
     <strong>
      <span style="color:#fe2c24;">
       ⚜️ 如果将资源写在try中会自动帮助，关掉资源的
      </span>
     </strong>
    </p>
    <pre><code class="language-java">    public static void main(String[] args) {
        try (Scanner scanner = new Scanner(System.in)) {
            int[] array = {1, 2, 3};
            System.out.println(array.length);
        } catch (NullPointerException e) {
            System.out.println("捕获到了一个空指针异常！");
        } catch (ArithmeticException e) {
            System.out.println("捕获到了一个算术异常！");
        } finally {
            System.out.println("进行资源关闭！");
        }
        System.out.println("其它代码逻辑！");
    }</code></pre>
    <p>
     下面看这一段代码
    </p>
    <pre><code class="language-java">    public static int func(int a) {
        try{
            if(a == 0) {
                throw  new ArithmeticException();
            }
            return a;
        } catch (ArithmeticException e) {
            System.out.println("算术异常！");
        } finally {
            return 20;
        }
    }

    public static void main(String[] args) {
        System.out.println(func(10));
    }</code></pre>
    <p>
     <img alt="" height="104" src="https://i-blog.csdnimg.cn/blog_migrate/bcf2a58c3c61363a8605154f37c793de.png" width="222"/>
    </p>
    <p>
     <span style="color:#fe2c24;">
      <strong>
       可以发现即使有return，finally也会被执行
      </strong>
     </span>
    </p>
    <blockquote>
     <p>
      <span style="color:#956fe7;">
       <strong>
        总结一下：
       </strong>
      </span>
     </p>
     <p>
      <span style="color:#956fe7;">
       <strong>
        throw抛出异常，throws声明异常
       </strong>
      </span>
     </p>
     <p>
      <span style="color:#956fe7;">
       <strong>
        finally语句一定会执行
       </strong>
      </span>
     </p>
    </blockquote>
    <h2 id="3.%E8%87%AA%E5%AE%9A%E4%B9%89%E5%BC%82%E5%B8%B8%E7%B1%BB">
     <span style="color:#b95514;">
      3.自定义异常类
     </span>
    </h2>
    <blockquote>
     <p>
      <span style="color:#1a439c;">
       <strong>
        虽然java中有很多异常类，但是在实际开发中所遇到的一些异常，不能完全表示，
       </strong>
      </span>
     </p>
     <p>
      <span style="color:#1a439c;">
       <strong>
        所以这就需要我们自定义异常类
       </strong>
      </span>
     </p>
    </blockquote>
    <div>
     <span style="color:#fe2c24;">
      <strong>
       举一个例子
      </strong>
     </span>
    </div>
    <div>
     <span style="color:#fe2c24;">
      <strong>
       先自定义一个运行时异常
      </strong>
     </span>
    </div>
    <div>
     <pre><code class="language-java">//自定义了一个运行时异常
public class MyException extends RuntimeException{
    public MyException() {

    }
    public MyException(String message) {
        super(message);
    }
}
</code></pre>
     <p>
      <span style="color:#956fe7;">
       <strong>
        写一个类来捕获这个自定义异常
       </strong>
      </span>
     </p>
     <pre><code class="language-java">public class Test04 {
    public static void func(int a ) {
        throw new MyException("呵呵！");
    }

    public static void main(String[] args) {
        try {
            func(20);
        }catch (MyException myException) {
            myException.printStackTrace();
        }finally {
            System.out.println("sadasdasd");
        }

    }
}</code></pre>
     <p>
      <span style="color:#fe2c24;">
       <strong>
        下面写一个用户登录的自定义异常类
       </strong>
      </span>
     </p>
     <pre><code class="language-java">class UserNameException extends RuntimeException {
    public UserNameException() {

    }
    public UserNameException(String message) {
        super(message);
    }
}
class PasswordException extends RuntimeException {

    public PasswordException() {
    }

    public PasswordException(String message) {
        super(message);
    }
}</code></pre>
     <pre><code class="language-java">public class LogIn {
    private static String uName = "admin";
    private static String pword = "1111";

    public static void loginInfo(String userName, String password) {
        if ( !uName.equals(userName)) {
            throw new UserNameException("用户名错误！");
        }
        if ( !pword.equals(password)) {
            throw new RuntimeException("密码错误！");

        }
        System.out.println("登录成功！");
    }

    public static void main(String[] args) {
        try {
            loginInfo("admin","1111");
        } catch (UserNameException e) {
            e.printStackTrace();
        } catch (PasswordException e) {
            e.printStackTrace();
        }
    }
}</code></pre>
     <p>
      注意：
     </p>
     <blockquote>
      <div>
       <span style="color:#fe2c24;">
        <strong>
         自定义异常默认会继承 Exception 或者 RuntimeException
        </strong>
       </span>
      </div>
      <div>
      </div>
      <div>
       <span style="color:#956fe7;">
        <strong>
         继承于 Exception 的异常默认是受查异常
        </strong>
       </span>
      </div>
      <div>
      </div>
      <div>
       <span style="color:#956fe7;">
        <strong>
         继承于 RuntimeException 的异常默认是非受查异常
        </strong>
       </span>
      </div>
     </blockquote>
    </div>
    <p>
    </p>
    <hr/>
    <p>
    </p>
   </div>
  </div>
 </article>
</div>


