---
arturl_encode: "68747470733a2f2f626c6f67:2e6373646e2e6e65742f77656978696e5f3333373031323531:2f61727469636c652f64657461696c732f3933323830303336"
layout: post
title: "解决用try-except-捕获assert函数产生的AssertionError异常时,导致断言失败的用例在测试报告中通过的问题..."
date: 2024-12-12 23:32:42 +08:00
description: "　　在使用Python3做自动化测试过程中可能会遇到,assert函数不加try except，就可"
keywords: "try assert断言失败生成测试报告"
categories: ['未分类']
tags: ['Python', 'Java', 'C']
artid: "93280036"
image:
  path: https://api.vvhan.com/api/bing?rand=sj&artid=93280036
  alt: "解决用try-except-捕获assert函数产生的AssertionError异常时,导致断言失败的用例在测试报告中通过的问题..."
render_with_liquid: false
featuredImage: https://bing.ee123.net/img/rand?artid=93280036
featuredImagePreview: https://bing.ee123.net/img/rand?artid=93280036
---

# 解决用try except 捕获assert函数产生的AssertionError异常时,导致断言失败的用例在测试报告中通过的问题...

在使用Python3做自动化测试过程中可能会遇到,assert函数不加try  except，就可以正常在报告里体现用例不通过，加上变成通过。

这是因为在使用try except 时,捕获了assert函数产生的AssertionError异常,导致异常没有上抛,这时只需要在后面加上 raise 就可以再次把它抛出。

```
        try:# 找到输入框并输入测试数据
            self.driver.find_element_by_id("kw").send_keys(testdata)
            # 找到搜索按钮,并单击
            self.driver.find_element_by_id("su").click()
            time.sleep(3)
            # 断言期望结果中是否出现页面源代码中
            self.assertIn(expectdata,self.driver.page_source)
            time.sleep(3)
      except AssertionError as e:
            logger.info(u"搜索\"%s\",期望\"%s\"失败" % (testdata, expectdata))
            raise 
        else:
            logger.info(u"搜索\"%s\",期望\"%s\"通过"%(testdata,expectdata))
```

转载于:https://www.cnblogs.com/fanjc/p/10072556.html